Traceback (most recent call last):
  File "/Users/brunamoura/PrevisorReconhecimento/.venv/lib/python3.9/site-packages/jupyter_cache/executors/utils.py", line 58, in single_nb_execution
    executenb(
  File "/Users/brunamoura/PrevisorReconhecimento/.venv/lib/python3.9/site-packages/nbclient/client.py", line 1314, in execute
    return NotebookClient(nb=nb, resources=resources, km=km, **kwargs).execute()
  File "/Users/brunamoura/PrevisorReconhecimento/.venv/lib/python3.9/site-packages/jupyter_core/utils/__init__.py", line 165, in wrapped
    return loop.run_until_complete(inner)
  File "/Library/Developer/CommandLineTools/Library/Frameworks/Python3.framework/Versions/3.9/lib/python3.9/asyncio/base_events.py", line 642, in run_until_complete
    return future.result()
  File "/Users/brunamoura/PrevisorReconhecimento/.venv/lib/python3.9/site-packages/nbclient/client.py", line 709, in async_execute
    await self.async_execute_cell(
  File "/Users/brunamoura/PrevisorReconhecimento/.venv/lib/python3.9/site-packages/nbclient/client.py", line 1062, in async_execute_cell
    await self._check_raise_for_error(cell, cell_index, exec_reply)
  File "/Users/brunamoura/PrevisorReconhecimento/.venv/lib/python3.9/site-packages/nbclient/client.py", line 918, in _check_raise_for_error
    raise CellExecutionError.from_cell_and_msg(cell, exec_reply_content)
nbclient.exceptions.CellExecutionError: An error occurred while executing the following cell:
------------------
colunas = [
    'DA_Polui/cont do ar', 
    'DA_Polui/cont do solo', 
    'DA_Polui/cont da Ã¡gua', 
    "DA_IncÃªndi parques/APA's/APP's", 
    'DA_Dimi/exauri hÃ­drico', 
    'DM_Descricao', 
    'DA_Descricao', 
    'PEPL_Descricao', 
    'PEPR_Descricao', 
    'DH_Descricao'
]

df_eventos_missing = df_eventos.copy()

df_eventos_missing = df_eventos_missing.dropna(subset=['PIB'])
#Existem dados para o PIB apenas atÃ© 2022.

df_eventos_missing['Total_Missing'] = df_eventos_missing[colunas].isnull().sum(axis=1)
df_eventos_missing['PIB_per_capita'] = df_eventos_missing['PIB'] / df_eventos_missing['Hab']

plt.figure(figsize=(10, 6))
sns.scatterplot(x='PIB_per_capita', y='Total_Missing', data=df_eventos_missing, hue='Status', palette='deep')
plt.title('RelaÃ§Ã£o entre renda per capita e dados ausentes')
plt.xlabel('PIB per capita')
plt.ylabel('Total de Valores Ausentes')
plt.show()

------------------


[0;31m---------------------------------------------------------------------------[0m
[0;31mKeyError[0m                                  Traceback (most recent call last)
File [0;32m~/PrevisorReconhecimento/.venv/lib/python3.9/site-packages/pandas/core/indexes/base.py:3805[0m, in [0;36mIndex.get_loc[0;34m(self, key)[0m
[1;32m   3804[0m [38;5;28;01mtry[39;00m:
[0;32m-> 3805[0m     [38;5;28;01mreturn[39;00m [38;5;28;43mself[39;49m[38;5;241;43m.[39;49m[43m_engine[49m[38;5;241;43m.[39;49m[43mget_loc[49m[43m([49m[43mcasted_key[49m[43m)[49m
[1;32m   3806[0m [38;5;28;01mexcept[39;00m [38;5;167;01mKeyError[39;00m [38;5;28;01mas[39;00m err:

File [0;32mindex.pyx:167[0m, in [0;36mpandas._libs.index.IndexEngine.get_loc[0;34m()[0m

File [0;32mindex.pyx:196[0m, in [0;36mpandas._libs.index.IndexEngine.get_loc[0;34m()[0m

File [0;32mpandas/_libs/hashtable_class_helper.pxi:7081[0m, in [0;36mpandas._libs.hashtable.PyObjectHashTable.get_item[0;34m()[0m

File [0;32mpandas/_libs/hashtable_class_helper.pxi:7089[0m, in [0;36mpandas._libs.hashtable.PyObjectHashTable.get_item[0;34m()[0m

[0;31mKeyError[0m: 'Hab'

The above exception was the direct cause of the following exception:

[0;31mKeyError[0m                                  Traceback (most recent call last)
Cell [0;32mIn[10], line 20[0m
[1;32m     17[0m [38;5;66;03m#Existem dados para o PIB apenas atÃ© 2022.[39;00m
[1;32m     19[0m df_eventos_missing[[38;5;124m'[39m[38;5;124mTotal_Missing[39m[38;5;124m'[39m] [38;5;241m=[39m df_eventos_missing[colunas][38;5;241m.[39misnull()[38;5;241m.[39msum(axis[38;5;241m=[39m[38;5;241m1[39m)
[0;32m---> 20[0m df_eventos_missing[[38;5;124m'[39m[38;5;124mPIB_per_capita[39m[38;5;124m'[39m] [38;5;241m=[39m df_eventos_missing[[38;5;124m'[39m[38;5;124mPIB[39m[38;5;124m'[39m] [38;5;241m/[39m [43mdf_eventos_missing[49m[43m[[49m[38;5;124;43m'[39;49m[38;5;124;43mHab[39;49m[38;5;124;43m'[39;49m[43m][49m
[1;32m     22[0m plt[38;5;241m.[39mfigure(figsize[38;5;241m=[39m([38;5;241m10[39m, [38;5;241m6[39m))
[1;32m     23[0m sns[38;5;241m.[39mscatterplot(x[38;5;241m=[39m[38;5;124m'[39m[38;5;124mPIB_per_capita[39m[38;5;124m'[39m, y[38;5;241m=[39m[38;5;124m'[39m[38;5;124mTotal_Missing[39m[38;5;124m'[39m, data[38;5;241m=[39mdf_eventos_missing, hue[38;5;241m=[39m[38;5;124m'[39m[38;5;124mStatus[39m[38;5;124m'[39m, palette[38;5;241m=[39m[38;5;124m'[39m[38;5;124mdeep[39m[38;5;124m'[39m)

File [0;32m~/PrevisorReconhecimento/.venv/lib/python3.9/site-packages/pandas/core/frame.py:4102[0m, in [0;36mDataFrame.__getitem__[0;34m(self, key)[0m
[1;32m   4100[0m [38;5;28;01mif[39;00m [38;5;28mself[39m[38;5;241m.[39mcolumns[38;5;241m.[39mnlevels [38;5;241m>[39m [38;5;241m1[39m:
[1;32m   4101[0m     [38;5;28;01mreturn[39;00m [38;5;28mself[39m[38;5;241m.[39m_getitem_multilevel(key)
[0;32m-> 4102[0m indexer [38;5;241m=[39m [38;5;28;43mself[39;49m[38;5;241;43m.[39;49m[43mcolumns[49m[38;5;241;43m.[39;49m[43mget_loc[49m[43m([49m[43mkey[49m[43m)[49m
[1;32m   4103[0m [38;5;28;01mif[39;00m is_integer(indexer):
[1;32m   4104[0m     indexer [38;5;241m=[39m [indexer]

File [0;32m~/PrevisorReconhecimento/.venv/lib/python3.9/site-packages/pandas/core/indexes/base.py:3812[0m, in [0;36mIndex.get_loc[0;34m(self, key)[0m
[1;32m   3807[0m     [38;5;28;01mif[39;00m [38;5;28misinstance[39m(casted_key, [38;5;28mslice[39m) [38;5;129;01mor[39;00m (
[1;32m   3808[0m         [38;5;28misinstance[39m(casted_key, abc[38;5;241m.[39mIterable)
[1;32m   3809[0m         [38;5;129;01mand[39;00m [38;5;28many[39m([38;5;28misinstance[39m(x, [38;5;28mslice[39m) [38;5;28;01mfor[39;00m x [38;5;129;01min[39;00m casted_key)
[1;32m   3810[0m     ):
[1;32m   3811[0m         [38;5;28;01mraise[39;00m InvalidIndexError(key)
[0;32m-> 3812[0m     [38;5;28;01mraise[39;00m [38;5;167;01mKeyError[39;00m(key) [38;5;28;01mfrom[39;00m [38;5;21;01merr[39;00m
[1;32m   3813[0m [38;5;28;01mexcept[39;00m [38;5;167;01mTypeError[39;00m:
[1;32m   3814[0m     [38;5;66;03m# If we have a listlike key, _check_indexing_error will raise[39;00m
[1;32m   3815[0m     [38;5;66;03m#  InvalidIndexError. Otherwise we fall through and re-raise[39;00m
[1;32m   3816[0m     [38;5;66;03m#  the TypeError.[39;00m
[1;32m   3817[0m     [38;5;28mself[39m[38;5;241m.[39m_check_indexing_error(key)

[0;31mKeyError[0m: 'Hab'

