Traceback (most recent call last):
  File "/Users/brunamoura/PrevisorReconhecimento/.venv/lib/python3.9/site-packages/jupyter_cache/executors/utils.py", line 58, in single_nb_execution
    executenb(
  File "/Users/brunamoura/PrevisorReconhecimento/.venv/lib/python3.9/site-packages/nbclient/client.py", line 1314, in execute
    return NotebookClient(nb=nb, resources=resources, km=km, **kwargs).execute()
  File "/Users/brunamoura/PrevisorReconhecimento/.venv/lib/python3.9/site-packages/jupyter_core/utils/__init__.py", line 165, in wrapped
    return loop.run_until_complete(inner)
  File "/Library/Developer/CommandLineTools/Library/Frameworks/Python3.framework/Versions/3.9/lib/python3.9/asyncio/base_events.py", line 642, in run_until_complete
    return future.result()
  File "/Users/brunamoura/PrevisorReconhecimento/.venv/lib/python3.9/site-packages/nbclient/client.py", line 709, in async_execute
    await self.async_execute_cell(
  File "/Users/brunamoura/PrevisorReconhecimento/.venv/lib/python3.9/site-packages/nbclient/client.py", line 1062, in async_execute_cell
    await self._check_raise_for_error(cell, cell_index, exec_reply)
  File "/Users/brunamoura/PrevisorReconhecimento/.venv/lib/python3.9/site-packages/nbclient/client.py", line 918, in _check_raise_for_error
    raise CellExecutionError.from_cell_and_msg(cell, exec_reply_content)
nbclient.exceptions.CellExecutionError: An error occurred while executing the following cell:
------------------
X_train_humanos[0]
------------------


[0;31m---------------------------------------------------------------------------[0m
[0;31mKeyError[0m                                  Traceback (most recent call last)
File [0;32m~/PrevisorReconhecimento/.venv/lib/python3.9/site-packages/pandas/core/indexes/base.py:3805[0m, in [0;36mIndex.get_loc[0;34m(self, key)[0m
[1;32m   3804[0m [38;5;28;01mtry[39;00m:
[0;32m-> 3805[0m     [38;5;28;01mreturn[39;00m [38;5;28;43mself[39;49m[38;5;241;43m.[39;49m[43m_engine[49m[38;5;241;43m.[39;49m[43mget_loc[49m[43m([49m[43mcasted_key[49m[43m)[49m
[1;32m   3806[0m [38;5;28;01mexcept[39;00m [38;5;167;01mKeyError[39;00m [38;5;28;01mas[39;00m err:

File [0;32mindex.pyx:167[0m, in [0;36mpandas._libs.index.IndexEngine.get_loc[0;34m()[0m

File [0;32mindex.pyx:196[0m, in [0;36mpandas._libs.index.IndexEngine.get_loc[0;34m()[0m

File [0;32mpandas/_libs/hashtable_class_helper.pxi:2606[0m, in [0;36mpandas._libs.hashtable.Int64HashTable.get_item[0;34m()[0m

File [0;32mpandas/_libs/hashtable_class_helper.pxi:2630[0m, in [0;36mpandas._libs.hashtable.Int64HashTable.get_item[0;34m()[0m

[0;31mKeyError[0m: 0

The above exception was the direct cause of the following exception:

[0;31mKeyError[0m                                  Traceback (most recent call last)
Cell [0;32mIn[9], line 1[0m
[0;32m----> 1[0m [43mX_train_humanos[49m[43m[[49m[38;5;241;43m0[39;49m[43m][49m

File [0;32m~/PrevisorReconhecimento/.venv/lib/python3.9/site-packages/pandas/core/series.py:1121[0m, in [0;36mSeries.__getitem__[0;34m(self, key)[0m
[1;32m   1118[0m     [38;5;28;01mreturn[39;00m [38;5;28mself[39m[38;5;241m.[39m_values[key]
[1;32m   1120[0m [38;5;28;01melif[39;00m key_is_scalar:
[0;32m-> 1121[0m     [38;5;28;01mreturn[39;00m [38;5;28;43mself[39;49m[38;5;241;43m.[39;49m[43m_get_value[49m[43m([49m[43mkey[49m[43m)[49m
[1;32m   1123[0m [38;5;66;03m# Convert generator to list before going through hashable part[39;00m
[1;32m   1124[0m [38;5;66;03m# (We will iterate through the generator there to check for slices)[39;00m
[1;32m   1125[0m [38;5;28;01mif[39;00m is_iterator(key):

File [0;32m~/PrevisorReconhecimento/.venv/lib/python3.9/site-packages/pandas/core/series.py:1237[0m, in [0;36mSeries._get_value[0;34m(self, label, takeable)[0m
[1;32m   1234[0m     [38;5;28;01mreturn[39;00m [38;5;28mself[39m[38;5;241m.[39m_values[label]
[1;32m   1236[0m [38;5;66;03m# Similar to Index.get_value, but we do not fall back to positional[39;00m
[0;32m-> 1237[0m loc [38;5;241m=[39m [38;5;28;43mself[39;49m[38;5;241;43m.[39;49m[43mindex[49m[38;5;241;43m.[39;49m[43mget_loc[49m[43m([49m[43mlabel[49m[43m)[49m
[1;32m   1239[0m [38;5;28;01mif[39;00m is_integer(loc):
[1;32m   1240[0m     [38;5;28;01mreturn[39;00m [38;5;28mself[39m[38;5;241m.[39m_values[loc]

File [0;32m~/PrevisorReconhecimento/.venv/lib/python3.9/site-packages/pandas/core/indexes/base.py:3812[0m, in [0;36mIndex.get_loc[0;34m(self, key)[0m
[1;32m   3807[0m     [38;5;28;01mif[39;00m [38;5;28misinstance[39m(casted_key, [38;5;28mslice[39m) [38;5;129;01mor[39;00m (
[1;32m   3808[0m         [38;5;28misinstance[39m(casted_key, abc[38;5;241m.[39mIterable)
[1;32m   3809[0m         [38;5;129;01mand[39;00m [38;5;28many[39m([38;5;28misinstance[39m(x, [38;5;28mslice[39m) [38;5;28;01mfor[39;00m x [38;5;129;01min[39;00m casted_key)
[1;32m   3810[0m     ):
[1;32m   3811[0m         [38;5;28;01mraise[39;00m InvalidIndexError(key)
[0;32m-> 3812[0m     [38;5;28;01mraise[39;00m [38;5;167;01mKeyError[39;00m(key) [38;5;28;01mfrom[39;00m [38;5;21;01merr[39;00m
[1;32m   3813[0m [38;5;28;01mexcept[39;00m [38;5;167;01mTypeError[39;00m:
[1;32m   3814[0m     [38;5;66;03m# If we have a listlike key, _check_indexing_error will raise[39;00m
[1;32m   3815[0m     [38;5;66;03m#  InvalidIndexError. Otherwise we fall through and re-raise[39;00m
[1;32m   3816[0m     [38;5;66;03m#  the TypeError.[39;00m
[1;32m   3817[0m     [38;5;28mself[39m[38;5;241m.[39m_check_indexing_error(key)

[0;31mKeyError[0m: 0

