Traceback (most recent call last):
  File "/Users/brunamoura/PrevisorReconhecimento/.venv/lib/python3.9/site-packages/jupyter_cache/executors/utils.py", line 58, in single_nb_execution
    executenb(
  File "/Users/brunamoura/PrevisorReconhecimento/.venv/lib/python3.9/site-packages/nbclient/client.py", line 1314, in execute
    return NotebookClient(nb=nb, resources=resources, km=km, **kwargs).execute()
  File "/Users/brunamoura/PrevisorReconhecimento/.venv/lib/python3.9/site-packages/jupyter_core/utils/__init__.py", line 165, in wrapped
    return loop.run_until_complete(inner)
  File "/Library/Developer/CommandLineTools/Library/Frameworks/Python3.framework/Versions/3.9/lib/python3.9/asyncio/base_events.py", line 642, in run_until_complete
    return future.result()
  File "/Users/brunamoura/PrevisorReconhecimento/.venv/lib/python3.9/site-packages/nbclient/client.py", line 709, in async_execute
    await self.async_execute_cell(
  File "/Users/brunamoura/PrevisorReconhecimento/.venv/lib/python3.9/site-packages/nbclient/client.py", line 1062, in async_execute_cell
    await self._check_raise_for_error(cell, cell_index, exec_reply)
  File "/Users/brunamoura/PrevisorReconhecimento/.venv/lib/python3.9/site-packages/nbclient/client.py", line 918, in _check_raise_for_error
    raise CellExecutionError.from_cell_and_msg(cell, exec_reply_content)
nbclient.exceptions.CellExecutionError: An error occurred while executing the following cell:
------------------
df_eventos_2018_2024 = df_eventos[(df_eventos['Ano_Evento'] >= 2018)]
df_eventos_2018_2024 = df_eventos_2018_2024.drop(columns=Rendapercapita)

print("Tamanho da base (2018 a 2024): ", df_eventos_2018_2024.shape)
print("Dados ausentes na base (2018 a 2024) \n", df_eventos_2018_2024.isna().sum())
------------------


[0;31m---------------------------------------------------------------------------[0m
[0;31mNameError[0m                                 Traceback (most recent call last)
Cell [0;32mIn[9], line 2[0m
[1;32m      1[0m df_eventos_2018_2024 [38;5;241m=[39m df_eventos[(df_eventos[[38;5;124m'[39m[38;5;124mAno_Evento[39m[38;5;124m'[39m] [38;5;241m>[39m[38;5;241m=[39m [38;5;241m2018[39m)]
[0;32m----> 2[0m df_eventos_2018_2024 [38;5;241m=[39m df_eventos_2018_2024[38;5;241m.[39mdrop(columns[38;5;241m=[39m[43mRendapercapita[49m)
[1;32m      4[0m [38;5;28mprint[39m([38;5;124m"[39m[38;5;124mTamanho da base (2018 a 2024): [39m[38;5;124m"[39m, df_eventos_2018_2024[38;5;241m.[39mshape)
[1;32m      5[0m [38;5;28mprint[39m([38;5;124m"[39m[38;5;124mDados ausentes na base (2018 a 2024) [39m[38;5;130;01m\n[39;00m[38;5;124m"[39m, df_eventos_2018_2024[38;5;241m.[39misna()[38;5;241m.[39msum())

[0;31mNameError[0m: name 'Rendapercapita' is not defined

